Workbook

Sheet Trades
A1: trade_no | B1: date | C1: time_et | D1: combo | E1: direction | F1: smt | G1: planned_entry | H1: planned_sl | I1: planned_tp | J1: planned_risk_pts | K1: actual_entry | L1: actual_exit | M1: outcome | N1: r_realized | O1: mae_R | P1: mfe_R | Q1: slippage_pts | R1: contracts | S1: pnl_usd | T1: notes
A2: 1 | J2: =IFERROR(IF(OR(G2="",H2=""),"",ABS(G2-H2)),"") | S2: =IFERROR(IF(OR(N2="",R2="",J2=""),"",N2*R2*J2*2),"")
A3: 2 | J3: =IFERROR(IF(OR(G3="",H3=""),"",ABS(G3-H3)),"") | S3: =IFERROR(IF(OR(N3="",R3="",J3=""),"",N3*R3*J3*2),"")
A4: 3 | J4: =IFERROR(IF(OR(G4="",H4=""),"",ABS(G4-H4)),"") | S4: =IFERROR(IF(OR(N4="",R4="",J4=""),"",N4*R4*J4*2),"")
A5: 4 | J5: =IFERROR(IF(OR(G5="",H5=""),"",ABS(G5-H5)),"") | S5: =IFERROR(IF(OR(N5="",R5="",J5=""),"",N5*R5*J5*2),"")
A6: 5 | J6: =IFERROR(IF(OR(G6="",H6=""),"",ABS(G6-H6)),"") | S6: =IFERROR(IF(OR(N6="",R6="",J6=""),"",N6*R6*J6*2),"")
A7: 6 | J7: =IFERROR(IF(OR(G7="",H7=""),"",ABS(G7-H7)),"") | S7: =IFERROR(IF(OR(N7="",R7="",J7=""),"",N7*R7*J7*2),"")
A8: 7 | J8: =IFERROR(IF(OR(G8="",H8=""),"",ABS(G8-H8)),"") | S8: =IFERROR(IF(OR(N8="",R8="",J8=""),"",N8*R8*J8*2),"")
A9: 8 | J9: =IFERROR(IF(OR(G9="",H9=""),"",ABS(G9-H9)),"") | S9: =IFERROR(IF(OR(N9="",R9="",J9=""),"",N9*R9*J9*2),"")
A10: 9 | J10: =IFERROR(IF(OR(G10="",H10=""),"",ABS(G10-H10)),"") | S10: =IFERROR(IF(OR(N10="",R10="",J10=""),"",N10*R10*J10*2),"")
A11: 10 | J11: =IFERROR(IF(OR(G11="",H11=""),"",ABS(G11-H11)),"") | S11: =IFERROR(IF(OR(N11="",R11="",J11=""),"",N11*R11*J11*2),"")
A12: 11 | J12: =IFERROR(IF(OR(G12="",H12=""),"",ABS(G12-H12)),"") | S12: =IFERROR(IF(OR(N12="",R12="",J12=""),"",N12*R12*J12*2),"")
A13: 12 | J13: =IFERROR(IF(OR(G13="",H13=""),"",ABS(G13-H13)),"") | S13: =IFERROR(IF(OR(N13="",R13="",J13=""),"",N13*R13*J13*2),"")
... A501: 500 | J501: =IFERROR(IF(OR(G501="",H501=""),"",ABS(G501-H501)),"") | S501: =IFERROR(IF(OR(N501="",R501="",J501=""),"",N501*R501*J501*2),"")

Sheet Summary
A1: Fractal Sweep — Forward-Test Summary
A2: Auto-updates from the Trades tab. Only WIN/LOSS rows count toward stats; SKIPPED and BE excluded from WR/EV.
A4: Headline stats | D4: Rolling windows
A5: Total trades logged | B5: =COUNTA(Trades!N2:N501) | D5: Last 30 — WR | E5: =IFERROR(COUNTIFS(OFFSET(Trades!M2,MAX(0,COUNTA(Trades!M2:M501)-30),0,MIN(30,COUNTA(Trades!M2:M501)),1),"WIN")/(COUNTIFS(OFFSET(Trades!M2,MAX(0,COUNTA(Trades!M2:M501)-30),0,MIN(30,COUNTA(Trades!M2:M501)),1),"WIN")+COUNTIFS(OFFSET(Trades!M2,MAX(0,COUNTA(Trades!M2:M501)-30),0,MIN(30,COUNTA(Trades!M2:M501)),1),"LOSS")),0)
A6: Wins | B6: =COUNTIF(Trades!M2:M501,"WIN") | D6: Last 30 — EV | E6: =IFERROR(SUMPRODUCT(OFFSET(Trades!N2,MAX(0,COUNTA(Trades!M2:M501)-30),0,MIN(30,COUNTA(Trades!M2:M501)),1))/MIN(30,COUNTA(Trades!M2:M501)),0)
A7: Losses | B7: =COUNTIF(Trades!M2:M501,"LOSS") | D7: Last 50 — WR | E7: =IFERROR(COUNTIFS(OFFSET(Trades!M2,MAX(0,COUNTA(Trades!M2:M501)-50),0,MIN(50,COUNTA(Trades!M2:M501)),1),"WIN")/(COUNTIFS(OFFSET(Trades!M2,MAX(0,COUNTA(Trades!M2:M501)-50),0,MIN(50,COUNTA(Trades!M2:M501)),1),"WIN")+COUNTIFS(OFFSET(Trades!M2,MAX(0,COUNTA(Trades!M2:M501)-50),0,MIN(50,COUNTA(Trades!M2:M501)),1),"LOSS")),0)
A8: Breakevens | B8: =COUNTIF(Trades!M2:M501,"BE") | D8: Last 50 — EV | E8: =IFERROR(SUMPRODUCT(OFFSET(Trades!N2,MAX(0,COUNTA(Trades!M2:M501)-50),0,MIN(50,COUNTA(Trades!M2:M501)),1))/MIN(50,COUNTA(Trades!M2:M501)),0)
A9: Skipped | B9: =COUNTIF(Trades!M2:M501,"SKIPPED") | D9: Last 100 — WR | E9: =IFERROR(COUNTIFS(OFFSET(Trades!M2,MAX(0,COUNTA(Trades!M2:M501)-100),0,MIN(100,COUNTA(Trades!M2:M501)),1),"WIN")/(COUNTIFS(OFFSET(Trades!M2,MAX(0,COUNTA(Trades!M2:M501)-100),0,MIN(100,COUNTA(Trades!M2:M501)),1),"WIN")+COUNTIFS(OFFSET(Trades!M2,MAX(0,COUNTA(Trades!M2:M501)-100),0,MIN(100,COUNTA(Trades!M2:M501)),1),"LOSS")),0)
A10: Win rate (excl BE) | B10: =IFERROR(B6/(B6+B7),0) | D10: Last 100 — EV | E10: =IFERROR(SUMPRODUCT(OFFSET(Trades!N2,MAX(0,COUNTA(Trades!M2:M501)-100),0,MIN(100,COUNTA(Trades!M2:M501)),1))/MIN(100,COUNTA(Trades!M2:M501)),0)
A11: Avg R per trade (EV) | B11: =IFERROR(SUM(Trades!N2:N501)/(B6+B7+B8),0)
A12: Profit factor | B12: =IFERROR(SUMIF(Trades!N2:N501,">0")/ABS(SUMIF(Trades!N2:N501,"<0")),0) | E12: running_R | F12: drawdown_R
A13: Total R | B13: =SUM(Trades!N2:N501) | E13: =IF(OR(Trades!M2="WIN",Trades!M2="LOSS"),Trades!N2,0) | F13: =MIN(0,E13-MAX($E$13:E13))
A14: Total P&L ($) | B14: =SUM(Trades!S2:S501) | E14: =IF(OR(Trades!M3="WIN",Trades!M3="LOSS"),E13+Trades!N3,E13) | F14: =MIN(0,E14-MAX($E$13:E14))
A15: Max drawdown (R) | B15: =IFERROR(MIN(F13:F512),0) | E15: =IF(OR(Trades!M4="WIN",Trades!M4="LOSS"),E14+Trades!N4,E14) | F15: =MIN(0,E15-MAX($E$13:E15))
A16: Forward-test status | E16: =IF(OR(Trades!M5="WIN",Trades!M5="LOSS"),E15+Trades!N5,E15) | F16: =MIN(0,E16-MAX($E$13:E16))
A17: (auto) | B17: =IF(B5<30,"⏳ Noise — keep tracking",IF(B5<100,"📊 Trend — too early to call",IF(B10<0.45,"🛑 STOP — WR below 45%",IF(B11<0,"🛑 STOP — EV negative","✓ On track")))) | E17: =IF(OR(Trades!M6="WIN",Trades!M6="LOSS"),E16+Trades!N6,E16) | F17: =MIN(0,E17-MAX($E$13:E17))
E18: =IF(OR(Trades!M7="WIN",Trades!M7="LOSS"),E17+Trades!N7,E17) | F18: =MIN(0,E18-MAX($E$13:E18))
E19: =IF(OR(Trades!M8="WIN",Trades!M8="LOSS"),E18+Trades!N8,E18) | F19: =MIN(0,E19-MAX($E$13:E19))
A20: Decision rules | E20: =IF(OR(Trades!M9="WIN",Trades!M9="LOSS"),E19+Trades!N9,E19) | F20: =MIN(0,E20-MAX($E$13:E20))
A21: 🛑 Stop trading if cumulative drawdown > 15R = $3,375
A22: 🛑 Stop if WR < 45% on Last-50 window
A23: 🛑 Stop if EV < 0R on Last-100 window
A24: ✓ Continue if WR 50-65% on rolling windows (within expected variance)
A25: ✓ Continue through 5-trade losing streaks (math says they're common at 59% WR)
E26: =IF(OR(Trades!M15="WIN",Trades!M15="LOSS"),E25+Trades!N15,E25) | F26: =MIN(0,E26-MAX($E$13:E26))
A27: Validation criteria — what 'edge confirmed' looks like after ~200 trades: | E27: =IF(OR(Trades!M16="WIN",Trades!M16="LOSS"),E26+Trades!N16,E26) | F27: =MIN(0,E27-MAX($E$13:E27))
A28: • WR consistently 55–62% on rolling windows
A29: • Avg R per trade between +0.10 and +0.18
A30: • Max drawdown stayed within 15R
A31: • Profit factor 1.4 or higher
E32: =IF(OR(Trades!M21="WIN",Trades!M21="LOSS"),E31+Trades!N21,E31) | F32: =MIN(0,E32-MAX($E$13:E32))
E33: =IF(OR(Trades!M22="WIN",Trades!M22="LOSS"),E32+Trades!N22,E32) | F33: =MIN(0,E33-MAX($E$13:E33))
E34: =IF(OR(Trades!M23="WIN",Trades!M23="LOSS"),E33+Trades!N23,E33) | F34: =MIN(0,E34-MAX($E$13:E34))
E35: =IF(OR(Trades!M24="WIN",Trades!M24="LOSS"),E34+Trades!N24,E34) | F35: =MIN(0,E35-MAX($E$13:E35))
E36: =IF(OR(Trades!M25="WIN",Trades!M25="LOSS"),E35+Trades!N25,E35) | F36: =MIN(0,E36-MAX($E$13:E36))
E37: =IF(OR(Trades!M26="WIN",Trades!M26="LOSS"),E36+Trades!N26,E36) | F37: =MIN(0,E37-MAX($E$13:E37))
E38: =IF(OR(Trades!M27="WIN",Trades!M27="LOSS"),E37+Trades!N27,E37) | F38: =MIN(0,E38-MAX($E$13:E38))
E39: =IF(OR(Trades!M28="WIN",Trades!M28="LOSS"),E38+Trades!N28,E38) | F39: =MIN(0,E39-MAX($E$13:E39))
E40: =IF(OR(Trades!M29="WIN",Trades!M29="LOSS"),E39+Trades!N29,E39) | F40: =MIN(0,E40-MAX($E$13:E40))
E41: =IF(OR(Trades!M30="WIN",Trades!M30="LOSS"),E40+Trades!N30,E40) | F41: =MIN(0,E41-MAX($E$13:E41))
...
